import { describe, it, expect, beforeEach, afterEach, vi } from 'vitest'
import { errorRecoveryService } from '../errorRecoveryService'

// Mock all dependencies
vi.mock('../networkErrorDetector', () => ({
  networkErrorDetector: {
    detectError: vi.fn().mockReturnValue({
      type: 'timeout',
      message: 'Network timeout',
      timestamp: new Date(),
      retryCount: 0
    }),
    shouldRetry: vi.fn().mockReturnValue(true),
    retryWithBackoff: vi.fn().mockResolvedValue('Success'),
    addToRetryQueue: vi.fn(),
    getNetworkStatus: vi.fn().mockReturnValue({
      isOnline: true,
      connectionType: 'wifi'
    }),
    getErrorHistory: vi.fn().mockReturnValue([]),
    getErrorStats: vi.fn().mockReturnValue({
      totalErrors: 0,
      errorsByType: {},
      averageRetryCount: 0
    })
  }
}))

vi.mock('../sessionConflictResolver', () => ({
  sessionConflictResolver: {
    getActiveConflicts: vi.fn().mockReturnValue([]),
    onConflictResolved: vi.fn(),
    getConflictHistory: vi.fn().mockReturnValue([])
  }
}))

vi.mock('../cacheCorruptionDetector', () => ({
  cacheCorruptionDetector: {
    performHealthScan: vi.fn().mockResolvedValue({
      totalEntries: 10,
      corruptedEntries: 0,
      healthPercentage: 100,
      lastScanTime: new Date()
    }),
    forceCacheCleanup: vi.fn().mockResolvedValue(undefined),
    getCorruptionReports: vi.fn().mockReturnValue([])
  }
}))

vi.mock('../authFallbackStrategies', () => ({
  authFallbackStrategies: {
    executeFallback: vi.fn().mockResolvedValue({
      success: true,
      strategy: 'token_refresh',
      action: 'retry',
      message: 'Token refreshed successfully'
    }),
    getExecutionStats: vi.fn().mockReturnValue({
      totalExecutions: 0,
      successRate: 100,
      strategyCounts: {},
      averageDuration: 0
    })
  }
}))

// Mock fetch for real API calls
global.fetch = vi.fn()

// Mock localStorage for real storage operations
const localStorageMock = {
  getItem: vi.fn(),
  setItem: vi.fn(),
  removeItem: vi.fn(),
  clear: vi.fn()
}

Object.defineProperty(window, 'localStorage', {
  value: localStorageMock
})

describe('ErrorRecoveryService Integration Tests', () => {
  beforeEach(async () => {
    vi.clearAllMocks()
    errorRecoveryService.clearOperationHistory()
    
    // Reset fetch mock
    ;(global.fetch as any).mockResolvedValue({
      ok: true,
      status: 200,
      json: () => Promise.resolve({ success: true })
    })
  })

  afterEach(() => {
    vi.clearAllTimers()
  })

  describe('Service Initialization', () => {
    it('should initialize all recovery components', async () => {
      // The service should be initialized automatically
      const healthCheck = await errorRecoveryService.performHealthCheck()
      
      expect(healthCheck).toHaveProperty('network')
      expect(healthCheck).toHaveProperty('session')
      expect(healthCheck).toHaveProperty('cache')
      expect(healthCheck).toHaveProperty('auth')
      expect(healthCheck).toHaveProperty('overall')
    })

    it('should set up global error handling', () => {
      // Test that fetch is intercepted
      expect(window.fetch).toBeDefined()
      
      // Test that unhandled rejection listener is set up
      const listeners = (window as any).addEventListener?.mock?.calls?.filter(
        (call: any) => call[0] === 'unhandledrejection'
      )
      
      // The service should have set up error handling
      expect(typeof window.fetch).toBe('function')
    })
  })

  describe('Network Error Recovery Integration', () => {
    it('should recover from network timeout with real retry logic', async () => {
      const networkError = {
        code: 'ECONNABORTED',
        message: 'timeout of 5000ms exceeded'
      }

      const context = {
        operation: 'api_call',
        url: '/api/test',
        method: 'GET'
      }

      const operation = await errorRecoveryService.recoverFromError(networkError, context)

      expect(operation.type).toBe('network')
      expect(operation.status).toBe('completed')
      expect(operation.result.recovered).toBe(true)
    })

    it('should handle real network disconnection scenario', async () => {
      // Simulate network going offline
      Object.defineProperty(navigator, 'onLine', {
        writable: true,
        value: false
      })

      const offlineError = {
        message: 'Failed to fetch'
      }

      const operation = await errorRecoveryService.recoverFromError(offlineError)

      expect(operation.type).toBe('network')
      // Should handle offline scenario appropriately
    })

    it('should process retry queue when network recovers', async () => {
      // Simulate network recovery
      Object.defineProperty(navigator, 'onLine', {
        writable: true,
        value: true
      })

      // Trigger online event
      const onlineEvent = new Event('online')
      window.dispatchEvent(onlineEvent)

      // Should process any queued operations
      await new Promise(resolve => setTimeout(resolve, 10))
    })
  })

  describe('Authentication Error Recovery Integration', () => {
    it('should recover from 401 error with token refresh', async () => {
      const authError = {
        response: { status: 401 },
        message: 'Unauthorized'
      }

      const context = {
        operation: 'validate',
        sessionData: { userId: 1, token: 'expired-token' }
      }

      // Mock successful token refresh
      ;(global.fetch as any).mockResolvedValueOnce({
        ok: true,
        json: () => Promise.resolve({
          access_token: 'new-token',
          refresh_token: 'new-refresh-token',
          expires_at: new Date(Date.now() + 3600000).toISOString()
        })
      })

      const operation = await errorRecoveryService.recoverFromError(authError, context)

      expect(operation.type).toBe('auth')
      expect(operation.status).toBe('completed')
      expect(operation.result.strategy).toBe('token_refresh')
    })

    it('should handle session validation failure with real API call', async () => {
      const sessionError = {
        response: { status: 401 },
        message: 'Session expired'
      }

      // Mock session validation failure
      ;(global.fetch as any).mockResolvedValueOnce({
        ok: false,
        status: 401,
        json: () => Promise.resolve({ error: 'Session expired' })
      })

      const operation = await errorRecoveryService.recoverFromError(sessionError, {
        type: 'session_validation'
      })

      expect(operation.type).toBe('auth')
    })

    it('should handle real logout scenario with cleanup', async () => {
      const logoutContext = {
        operation: 'logout',
        userId: 1,
        sessionId: 'session-123'
      }

      // Mock logout API call
      ;(global.fetch as any).mockResolvedValueOnce({
        ok: true,
        json: () => Promise.resolve({ success: true })
      })

      const operation = await errorRecoveryService.recoverFromError(
        new Error('Logout required'),
        logoutContext
      )

      expect(operation.type).toBe('auth')
    })
  })

  describe('Cache Corruption Recovery Integration', () => {
    it('should recover from cache corruption with real cleanup', async () => {
      // Mock corrupted cache data
      localStorageMock.getItem.mockImplementation((key) => {
        if (key === 'cache_corrupted') {
          return 'invalid json {'
        }
        return null
      })

      const cacheError = {
        name: 'QuotaExceededError',
        message: 'Storage quota exceeded'
      }

      const operation = await errorRecoveryService.recoverFromError(cacheError)

      expect(operation.type).toBe('cache')
      expect(operation.status).toBe('completed')
    })

    it('should handle real storage quota exceeded scenario', async () => {
      const quotaError = new Error('QuotaExceededError')
      quotaError.name = 'QuotaExceededError'

      // Mock storage cleanup
      localStorageMock.clear.mockImplementation(() => {
        // Simulate successful cleanup
      })

      const operation = await errorRecoveryService.recoverFromError(quotaError)

      expect(operation.type).toBe('cache')
    })
  })

  describe('Session Conflict Recovery Integration', () => {
    it('should resolve concurrent login conflict', async () => {
      const conflictError = {
        type: 'session_conflict',
        message: 'Multiple sessions detected'
      }

      const context = {
        type: 'concurrent_login',
        currentSession: { sessionId: 'session-1', userId: 1 },
        conflictingSession: { sessionId: 'session-2', userId: 1 }
      }

      const operation = await errorRecoveryService.recoverFromError(conflictError, context)

      expect(operation.type).toBe('session')
    })

    it('should handle token mismatch between tabs', async () => {
      const tokenMismatchError = {
        type: 'token_mismatch',
        message: 'Token mismatch detected'
      }

      const operation = await errorRecoveryService.recoverFromError(tokenMismatchError)

      expect(operation.type).toBe('session')
    })
  })

  describe('End-to-End Recovery Scenarios', () => {
    it('should handle complete authentication flow failure and recovery', async () => {
      // Simulate complete auth failure scenario
      const authFailure = {
        response: { status: 401 },
        message: 'Authentication failed'
      }

      // Mock token refresh failure, then session recovery success
      ;(global.fetch as any)
        .mockResolvedValueOnce({
          ok: false,
          status: 401
        })
        .mockResolvedValueOnce({
          ok: true,
          json: () => Promise.resolve({ valid: true })
        })

      const operation = await errorRecoveryService.recoverFromError(authFailure, {
        operation: 'login',
        attemptCount: 1
      })

      expect(operation.type).toBe('auth')
      expect(['completed', 'failed']).toContain(operation.status)
    })

    it('should handle network failure with offline fallback', async () => {
      // Simulate network failure
      Object.defineProperty(navigator, 'onLine', {
        writable: true,
        value: false
      })

      const networkFailure = {
        message: 'Failed to fetch'
      }

      // Mock cached session data
      localStorageMock.getItem.mockReturnValue(JSON.stringify({
        user: { id: 1, name: 'User' },
        token: 'cached-token',
        expiresAt: new Date(Date.now() + 3600000).toISOString()
      }))

      const operation = await errorRecoveryService.recoverFromError(networkFailure, {
        operation: 'validate'
      })

      expect(operation.type).toBe('network')
    })

    it('should handle cascading failures with multiple recovery attempts', async () => {
      // First attempt fails
      const initialError = {
        response: { status: 500 },
        message: 'Server error'
      }

      const operation = await errorRecoveryService.recoverFromError(initialError, {
        operation: 'api_call',
        attemptCount: 1
      })

      // Should attempt recovery
      expect(operation.retryCount).toBeGreaterThanOrEqual(0)
      expect(operation.maxRetries).toBeGreaterThan(0)
    })
  })

  describe('Real-time Error Monitoring', () => {
    it('should monitor and respond to real fetch errors', async () => {
      // Mock fetch to fail
      ;(global.fetch as any).mockRejectedValueOnce(new Error('Network error'))

      try {
        await fetch('/api/test')
      } catch (error) {
        // Error should be caught and handled by global error handler
      }

      // Should have triggered error recovery
      await new Promise(resolve => setTimeout(resolve, 10))
    })

    it('should handle unhandled promise rejections', async () => {
      const rejectionError = new Error('Unhandled auth error')
      rejectionError.name = 'AuthError'

      // Simulate unhandled rejection
      const rejectionEvent = new PromiseRejectionEvent('unhandledrejection', {
        promise: Promise.reject(rejectionError),
        reason: rejectionError
      })

      window.dispatchEvent(rejectionEvent)

      // Should trigger error recovery
      await new Promise(resolve => setTimeout(resolve, 10))
    })
  })

  describe('Performance and Health Monitoring', () => {
    it('should provide comprehensive health check', async () => {
      const health = await errorRecoveryService.performHealthCheck()

      expect(health.network).toHaveProperty('isOnline')
      expect(health.session).toHaveProperty('activeConflicts')
      expect(health.cache).toHaveProperty('healthPercentage')
      expect(health.auth).toHaveProperty('successRate')
      expect(['healthy', 'degraded', 'critical']).toContain(health.overall)
    })

    it('should track recovery statistics over time', async () => {
      // Perform multiple recovery operations
      const errors = [
        { code: 'ECONNABORTED' },
        { response: { status: 401 } },
        { name: 'QuotaExceededError' }
      ]

      for (const error of errors) {
        await errorRecoveryService.recoverFromError(error)
      }

      const stats = errorRecoveryService.getRecoveryStats()

      expect(stats.totalOperations).toBe(3)
      expect(stats.recoveryByType).toHaveProperty('network')
      expect(stats.recoveryByType).toHaveProperty('auth')
      expect(stats.recoveryByType).toHaveProperty('cache')
      expect(stats.averageRecoveryTime).toBeGreaterThanOrEqual(0)
    })

    it('should maintain recent operations history', async () => {
      await errorRecoveryService.recoverFromError({
        message: 'Test error'
      })

      const operations = errorRecoveryService.getOperations()
      expect(operations).toHaveLength(1)
      expect(operations[0].startTime).toBeInstanceOf(Date)
    })
  })

  describe('Configuration and Customization', () => {
    it('should allow configuration updates', () => {
      const newConfig = {
        enableAutoRecovery: false,
        maxRetries: 5,
        retryDelay: 2000
      }

      errorRecoveryService.updateConfig(newConfig)

      const config = errorRecoveryService.getConfig()
      expect(config.enableAutoRecovery).toBe(false)
      expect(config.maxRetries).toBe(5)
      expect(config.retryDelay).toBe(2000)
    })

    it('should respect disabled auto-recovery', async () => {
      errorRecoveryService.updateConfig({ enableAutoRecovery: false })

      const error = { message: 'Test error' }
      const operation = await errorRecoveryService.recoverFromError(error)

      // Should still create operation but may not auto-retry
      expect(operation).toBeDefined()
    })
  })

  describe('Real Application Integration', () => {
    it('should integrate with real Vue.js application state', async () => {
      // Mock Vue store updates
      const mockStore = {
        commit: vi.fn(),
        dispatch: vi.fn(),
        state: { user: null, token: null }
      }

      const authError = {
        response: { status: 401 },
        message: 'Token expired'
      }

      const operation = await errorRecoveryService.recoverFromError(authError, {
        store: mockStore,
        route: '/dashboard'
      })

      expect(operation.type).toBe('auth')
    })

    it('should handle real Docker environment scenarios', async () => {
      // Mock Docker-specific network conditions
      const dockerNetworkError = {
        code: 'ENOTFOUND',
        message: 'getaddrinfo ENOTFOUND backend'
      }

      const operation = await errorRecoveryService.recoverFromError(dockerNetworkError, {
        environment: 'docker',
        service: 'backend'
      })

      expect(operation.type).toBe('network')
    })

    it('should work with real browser storage limitations', async () => {
      // Mock browser storage quota
      Object.defineProperty(navigator, 'storage', {
        value: {
          estimate: () => Promise.resolve({
            usage: 9.5 * 1024 * 1024, // 9.5MB used
            quota: 10 * 1024 * 1024   // 10MB quota
          })
        }
      })

      const storageError = new Error('QuotaExceededError')
      storageError.name = 'QuotaExceededError'

      const operation = await errorRecoveryService.recoverFromError(storageError)

      expect(operation.type).toBe('cache')
    })
  })

  describe('Error Recovery Edge Cases', () => {
    it('should handle recovery service failure gracefully', async () => {
      // Mock all recovery methods to fail
      const mockError = new Error('Recovery service failure')
      
      vi.mocked(errorRecoveryService as any).executeNetworkRecovery = vi.fn().mockRejectedValue(mockError)

      const operation = await errorRecoveryService.recoverFromError({
        code: 'ECONNABORTED'
      })

      expect(operation.status).toBe('failed')
      expect(operation.error).toBeDefined()
    })

    it('should handle concurrent recovery operations', async () => {
      const error = { message: 'Concurrent test' }

      // Start multiple recovery operations simultaneously
      const operations = await Promise.all([
        errorRecoveryService.recoverFromError(error),
        errorRecoveryService.recoverFromError(error),
        errorRecoveryService.recoverFromError(error)
      ])

      // All should complete
      expect(operations).toHaveLength(3)
      operations.forEach(op => {
        expect(['completed', 'failed']).toContain(op.status)
      })
    })

    it('should handle memory constraints with large error history', async () => {
      // Generate many recovery operations
      for (let i = 0; i < 100; i++) {
        await errorRecoveryService.recoverFromError({
          message: `Error ${i}`
        })
      }

      const operations = errorRecoveryService.getOperations()
      
      // Should maintain reasonable history size
      expect(operations.length).toBeLessThanOrEqual(100)
    })
  })
})